Workbook

Sheet Provisionsberechnung
A1: Mitarbeiter: | B1: Joaquin Vega | H1: Jahresbduget | I1: Budget/Q | K1: Variables Gehalt bei 100% ZEG | M1: Variables Gehalt bei 100% ZEG / Periode
A2: Geschäftsjahr: | B2: 2026 | D2: Consultant | H2: 440000 | I2: =SUM(H2/4) -> 110000 | K2: 40000 | M2: =SUM(K2/4) -> 10000
A3: Heute: | B3: =TODAY() -> 46119 | D3: Civil Engineering
A5: Kandidat | B5: Kunde | C5: RG-Nr. | D5: Start-Datum Kandidat | E5: vorauss. Garantie-Ende (vorb.PZ-Verlängerung) | F5: Net Fee total | G5: Zuteilung Punkte | H5: Zuteilung Net Fee | I5: Zielerreichung und Auszahlung
A7: Quartal 1
A8: Jan Osterwalder | B8: B+S AG | C8: FN2026.01.0913 | D8: 46142 | E8: 46203 | F8: 28000 | G8: 1 | H8: =SUM(F8/2*G8) -> 14000 | I8: Q1 erzielte provisorischer Net Fees | K8: Q1 Budget | M8: P1 ZEG | P8: Q1 Provisionsstufe | W8: Auszahlungs-vorschlag | Y8: Q1 effektiver Auszahlungs-betrag | AA8: =IF(AA16>=W16,"ok","Überzahlung") -> ok
A9: Michael Vidal | B9: Frutiger AG | C9: FN2026.02.0901 | D9: 46266 | E9: 46356 | F9: 49998 | G9: 1 | H9: =SUM(F9/2*G9) -> 24999
A10: Thomas Aeschbacher | B10: Hefti.Hess.Martignoni. | C10: FN2026.03.0911 | D10: 46235 | E10: 46326 | F10: 50899.95 | G10: 1 | H10: =SUM(F10/2*G10) -> 25449.975 | W10: =SUM(U16-Y4) -> 10240
A11: Pascal Bader | B11: Selmoni Ingenieur AG | C11: FN2026.03.0913 | D11: 46174 | E11: 46265 | F11: 22000 | G11: 2 | H11: =SUM(F11/2*G11) -> 22000 | I11: =SUM(H8:H18) -> 129945.23 | K11: =SUM($I$2) -> 110000 | M11: =SUM(Provisionsstaffel!K10) -> 1.1813203 | P11: =SUM(Provisionsstaffel!M10) -> 1.28 | Y11: 0
A12: Daniel Maurer | B12: Büchi Bauunternehmung AG | C12: FN2026.03.0917 | D12: 46204 | E12: 46295 | F12: 30875 | G12: 2 | H12: =SUM(F12/2*G12) -> 30875
A13: Morgane Giorgi | B13: Grolimund + Partner AG | C13: FN2026.03.0919 | D13: 46174 | E13: 46265 | F13: 25242.51 | G13: 1 | H13: =SUM(F13/2*G13) -> 12621.255 | I13: kummulierte provisorische Net Fees | K13: kummuliertes Budget | M13: kummulierter ZEG | P13: kummulierte Provisionsstufe | S13: kummulierte provis.Provision | U13: kummulierte 80% Abschlagszahlung | W13: kummulierte 20%-Rücklage | Y13: Kummulation aller Auszahlungen | AA13: kummulierte Restanz nach Q1
H14: =SUM(F14/2*G14) -> 0
H15: =SUM(F15/2*G15) -> 0
H16: =SUM(F16/2*G16) -> 0 | I16: =SUM(I11) -> 129945.23 | K16: =SUM(K11*1) -> 110000 | M16: =SUM(Provisionsstaffel!L10) -> 1.18 | P16: =SUM(Provisionsstaffel!M10) -> 1.28 | S16: =SUM(Provisionsstaffel!N10) -> 12800 | U16: =SUM(S16*0.8) -> 10240 | W16: =SUM(S16*0.2) -> 2560 | Y16: =SUM(Y11) -> 0 | AA16: =SUM(S16-Y16) -> 12800
H17: =SUM(F17/2*G17) -> 0
H18: =SUM(F18/2*G18) -> 0
A20: Quartal 2
H21: =SUM(F21/2*G21) -> 0 | I21: Q2 erzielte provisorischer Net Fees | K21: Q2 Budget | M21: Q2 ZEG | P21: Q2 Provisionsstufe | W21: Auszahlungs-vorschlag | Y21: Q2 effektiver Auszahlungs-betrag | AA21: =IF(AA29>=W29,"ok","Überzahlung") -> ok
H22: =SUM(F22/2*G22) -> 0
H23: =SUM(F23/2*G23) -> 0 | W23: =SUM(U29-Y16) -> 4480
H24: =SUM(F24/2*G24) -> 0 | I24: =SUM(H21:H29) -> 0 | K24: =SUM($I$2) -> 110000 | M24: =SUM(Provisionsstaffel!F11) -> 0 | P24: =SUM(Provisionsstaffel!D11) -> #N/A | Y24: 0
H25: =SUM(F25/2*G25) -> 0
H26: =SUM(F26/2*G26) -> 0 | I26: kummulierte provisorische Net Fees | K26: kummuliertes Budget | M26: kummulierter ZEG | P26: kummulierte Provisionsstufe | S26: kummulierte provis.Provision | U26: kummulierte 80% Abschlagszahlung | W26: kummulierte 20%-Rücklage | Y26: Kummulation aller Auszahlungen | AA26: kummulierte Restanz nach Q2
H27: =SUM(F27/2*G27) -> 0
H28: =SUM(F28/2*G28) -> 0
H29: =SUM(F29/2*G29) -> 0 | I29: =SUM(I16,I24) -> 129945.23 | K29: =SUM(I2*2) -> 220000 | M29: =SUM(Provisionsstaffel!L11) -> 0.59 | P29: =SUM(Provisionsstaffel!M11) -> 0.28 | S29: =SUM(Provisionsstaffel!N11) -> 5600 | U29: =SUM(S29*0.8) -> 4480 | W29: =SUM(S29*0.2) -> 1120 | Y29: =SUM(Y16,Y24) -> 0 | AA29: =SUM(S29-Y29) -> 5600
A32: Quartal 3
H33: =SUM(F33/2*G33) -> 0 | I33: Q3 erzielte provisorischer Net Fees | K33: Q3 Budget | M33: Q3 ZEG | P33: Q3 Provisionsstufe | W33: Auszahlungs-vorschlag | Y33: Q3 effektiver Auszahlungs-betrag | AA33: =IF(AA41>=W41,"ok","Überzahlung") -> ok
H34: =SUM(F34/2*G34) -> 0
H35: =SUM(F35/2*G35) -> 0 | W35: =SUM(U41-Y29) -> 0
H36: =SUM(F36/2*G36) -> 0 | I36: =SUM(H33:H42) -> 0 | K36: =SUM($I$2) -> 110000 | M36: =SUM(Provisionsstaffel!F12) -> 0 | P36: =SUM(Provisionsstaffel!D12) -> #N/A
H37: =SUM(F37/2*G37) -> 0
H38: =SUM(F38/2*G38) -> 0 | I38: kummulierte provisorische Net Fees | K38: kummuliertes Budget | M38: kummulierter ZEG | P38: kummulierte Provisionsstufe | S38: kummulierte provis.Provision | U38: kummulierte 80% Abschlagszahlung | W38: kummulierte 20%-Rücklage | Y38: Kummulation aller Auszahlungen | AA38: kummulierte Restanz nach Q3
H39: =SUM(F39/2*G39) -> 0
H40: =SUM(F40/2*G40) -> 0
H41: =SUM(F41/2*G41) -> 0 | I41: =SUM(I29,I36) -> 129945.23 | K41: =SUM(I2*3) -> 330000 | M41: =SUM(Provisionsstaffel!L12) -> 0.39 | P41: =SUM(Provisionsstaffel!M12) -> 0 | S41: =SUM(Provisionsstaffel!N12) -> 0 | U41: =SUM(S41*0.8) -> 0 | W41: =SUM(S41*0.2) -> 0 | Y41: =SUM(Y29,Y36) -> 0 | AA41: =SUM(S41-Y41) -> 0
H42: =SUM(F42/2*G42) -> 0
A44: Quartal 4
H45: =SUM(F45/2*G45) -> 0 | I45: Q4 erzielte provisorischer Net Fees | K45: Q4 Budget | M45: Q4 ZEG | P45: Q4 Provisionsstufe | W45: Auszahlungs-vorschlag | Y45: Q4 effektiver Auszahlungs-betrag | AA45: =IF(AA53>=W53,"ok","Überzahlung") -> #N/A
H46: =SUM(F46/2*G46) -> 0
...

Sheet Provisionsstaffel
A2: ZEG | B2: Provisionssatz | J2: pro Q
A3: 0.3 | B3: 0 | H3: Budget | I3: =SUM(Provisionsberechnung!H2) -> 440000 | J3: =SUM(Provisionsberechnung!I2) -> 110000
A4: 0.31 | B4: 0 | H4: Net Fees | I4: 400000 | J4: 100000
A5: 0.32 | B5: 0 | H5: ZEG gerundet | I5: =SUM(I4/I3) -> 0.90909091
A6: 0.33 | B6: 0 | H6: Anwendbarer Provisionssatz | I6: =VLOOKUP(I5,A2:B273,2) -> 0.8
A7: 0.34 | B7: 0 | H7: Variabler Zielbetrag 100% | I7: =SUM(Provisionsberechnung!K2) -> 40000 | J7: =SUM(Provisionsberechnung!M2) -> 10000
A8: 0.35 | B8: 0 | Q8: Abschlagszahlungen Unterjährig
A9: 0.36 | B9: 0 | D9: Provisionssatz pro P | E9: ZEG pro P gerundet | F9: ZEG pro P | G9: effektive NFs pro P | I9: Budget | J9: effektive Net Fees | K9: ZEG | L9: ZEG gerundet | M9: Anwendbarer Provisionssatz | N9: Provisorischer Anspruch 100% | O9: 80% Abschlagszahlung (Vorschuss) | P9: 20% Rücklage | Q9: Saldo 80% Abschlag | R9: Ausbezahlt | S9: Ausbezahlt total | T9: Restanz per Periode | U9: Restanz verrechnet INKL. 20% Rücklage
A10: 0.37 | B10: 0 | C10: =SUM($J$7*D10) -> 12800 | D10: =VLOOKUP(E10,$A$2:$B$274,2) -> 1.28 | E10: =ROUND(F10,2) -> 1.18 | F10: =SUM(G10/$J$3) -> 1.1813203 | G10: =SUM(Provisionsberechnung!I11) -> 129945.23 | H10: P1 | I10: =SUM(I3/4*1) -> 110000 | J10: =SUM(Provisionsberechnung!I11) -> 129945.23 | K10: =SUM(J10/I10) -> 1.1813203 | L10: =ROUND(K10,2) -> 1.18 | M10: =VLOOKUP(L10,A3:B274,2) -> 1.28 | N10: =SUM($I$7/4*1*M10) -> 12800 | O10: =SUM(N10*80%) -> 10240 | P10: =SUM(N10*20%) -> 2560 | Q10: =SUM(O10) -> 10240 | R10: 5000 | S10: =SUM(R10) -> 5000 | T10: =SUM(O10-R10) -> 5240 | U10: =SUM(P10+T10) -> 7800
A11: 0.38 | B11: 0 | C11: =SUM($J$7*D11) -> #N/A | D11: =VLOOKUP(E11,$A$2:$B$274,2) -> #N/A | E11: =ROUND(F11,2) -> 0 | F11: =SUM(G11/$J$3) -> 0 | G11: =SUM(Provisionsberechnung!I24) -> 0 | H11: P2 | I11: =SUM(I3/4*2) -> 220000 | J11: =SUM(G10:G11) -> 129945.23 | K11: =SUM(J11/I11) -> 0.59066014 | L11: =ROUND(K11,2) -> 0.59 | M11: =VLOOKUP(L11,A3:B275,2) -> 0.28 | N11: =SUM($I$7/4*2*M11) -> 5600 | O11: =SUM(N11*80%) -> 4480 | P11: =SUM(N11*20%) -> 1120 | Q11: =SUM(O11-S10) -> -520 | S11: =SUM(S10+R11) -> 5000 | T11: =SUM(Q11-R11) -> -520 | U11: =SUM(P11+T11) -> 600
A12: 0.39 | B12: 0 | C12: =SUM($J$7*D12) -> #N/A | D12: =VLOOKUP(E12,$A$2:$B$274,2) -> #N/A | E12: =ROUND(F12,2) -> 0 | F12: =SUM(G12/$J$3) -> 0 | G12: =SUM(Provisionsberechnung!I36) -> 0 | H12: P3 | I12: =SUM(I3/4*3) -> 330000 | J12: =SUM(G10:G12) -> 129945.23 | K12: =SUM(J12/I12) -> 0.39377342 | L12: =ROUND(K12,2) -> 0.39 | M12: =VLOOKUP(L12,A4:B276,2) -> 0 | N12: =SUM($I$7/4*3*M12) -> 0 | O12: =SUM(N12*80%) -> 0 | P12: =SUM(N12*20%) -> 0 | Q12: =SUM(O12-S11) -> -5000 | R12: 0 | S12: =SUM(S11+R12) -> 5000 | T12: =SUM(Q12-R12) -> -5000 | U12: =SUM(P12+T12) -> -5000
A13: 0.4 | B13: 0 | D13: =VLOOKUP(E13,$A$2:$B$274,2) -> #N/A | E13: =ROUND(F13,2) -> 0 | F13: =SUM(G13/$J$3) -> 0 | G13: =SUM(Provisionsberechnung!I48) -> 0 | H13: P4 | I13: =SUM(I3/4*4) -> 440000 | J13: =SUM(G10:G13) -> 129945.23 | K13: =SUM(J13/I13) -> 0.29533007 | L13: =ROUND(K13,2) -> 0.3 | M13: =VLOOKUP(L13,A5:B277,2) -> #N/A | N13: =SUM($I$7/4*4*M13) -> #N/A | O13: =SUM(N13*80%) -> #N/A | P13: =SUM(N13*20%) -> #N/A | Q13: =SUM(O13-S12) -> #N/A | R13: 0 | S13: =SUM(S12+R13) -> 5000 | T13: =SUM(Q13-R13) -> #N/A | U13: =SUM(P13+T13) -> #N/A
A14: 0.41 | B14: 0
A15: 0.42 | B15: 0
A16: 0.43 | B16: 0
A17: 0.44 | B17: 0
A18: 0.45 | B18: 0
A19: 0.46 | B19: 0
A20: 0.47 | B20: 0
A21: 0.48 | B21: 0
A22: 0.49 | B22: 0
A23: 0.5 | B23: 0.1
A24: 0.51 | B24: 0.12
A25: 0.52 | B25: 0.14
... A273: 3 | B273: 3.1
